Workbook

Sheet Sales_Data
A1: Data | B1: Store | C1: Category | D1: Product | E1: Units Sold | F1: Revenue | G1: Cost | H1: Profit | I1: Inventory
A2: 45658 | B2: {=INDEX(Reference_Table!$A$1:$A$3,RANDBETWEEN(1,3))} -> Tampa | C2: {=INDEX(Reference_Table!$B$1:$B$3,RANDBETWEEN(1,3))} -> Apparel | D2: {=IF(C2="Footwear",INDEX(Reference_Table!$C$1:$C$3,RANDBETWEEN(1,3)), IF(C2="Apparel",INDEX(Reference_Table!$D$1:$D$3,RANDBETWEEN(1,3)), INDEX(Reference_Table!$E$1:$E$3,RANDBETWEEN(1,3))))} -> Nike Shorts | E2: =RANDBETWEEN(5,100) -> 76 | F2: =IF(C2="Footwear",E2*RANDBETWEEN(50,200), IF(C2="Apparel",E2*RANDBETWEEN(20,100), E2*RANDBETWEEN(20,200))) -> 6612 | G2: =F2*RANDBETWEEN(60,80)/100 -> 4033.32 | H2: =F2-G2 -> 2578.68 | I2: =RANDBETWEEN(0,40) -> 36
A3: 45658 | B3: {=INDEX(Reference_Table!$A$1:$A$3,RANDBETWEEN(1,3))} -> Tampa | C3: {=INDEX(Reference_Table!$B$1:$B$3,RANDBETWEEN(1,3))} -> Apparel | D3: {=IF(C3="Footwear",INDEX(Reference_Table!$C$1:$C$3,RANDBETWEEN(1,3)), IF(C3="Apparel",INDEX(Reference_Table!$D$1:$D$3,RANDBETWEEN(1,3)), INDEX(Reference_Table!$E$1:$E$3,RANDBETWEEN(1,3))))} -> Adidas Joggers | E3: =RANDBETWEEN(5,100) -> 76 | F3: =IF(C3="Footwear",E3*RANDBETWEEN(50,200), IF(C3="Apparel",E3*RANDBETWEEN(20,100), E3*RANDBETWEEN(20,200))) -> 6156 | G3: =F3*RANDBETWEEN(60,80)/100 -> 3939.84 | H3: =F3-G3 -> 2216.16 | I3: =RANDBETWEEN(0,40) -> 33
A4: 45658 | B4: {=INDEX(Reference_Table!$A$1:$A$3,RANDBETWEEN(1,3))} -> Clearwater | C4: {=INDEX(Reference_Table!$B$1:$B$3,RANDBETWEEN(1,3))} -> Footwear | D4: {=IF(C4="Footwear",INDEX(Reference_Table!$C$1:$C$3,RANDBETWEEN(1,3)), IF(C4="Apparel",INDEX(Reference_Table!$D$1:$D$3,RANDBETWEEN(1,3)), INDEX(Reference_Table!$E$1:$E$3,RANDBETWEEN(1,3))))} -> Nike Running | E4: =RANDBETWEEN(5,100) -> 25 | F4: =IF(C4="Footwear",E4*RANDBETWEEN(50,200), IF(C4="Apparel",E4*RANDBETWEEN(20,100), E4*RANDBETWEEN(20,200))) -> 3050 | G4: =F4*RANDBETWEEN(60,80)/100 -> 2013 | H4: =F4-G4 -> 1037 | I4: =RANDBETWEEN(0,40) -> 25
A5: 45689 | B5: {=INDEX(Reference_Table!$A$1:$A$3,RANDBETWEEN(1,3))} -> Clearwater | C5: {=INDEX(Reference_Table!$B$1:$B$3,RANDBETWEEN(1,3))} -> Footwear | D5: {=IF(C5="Footwear",INDEX(Reference_Table!$C$1:$C$3,RANDBETWEEN(1,3)), IF(C5="Apparel",INDEX(Reference_Table!$D$1:$D$3,RANDBETWEEN(1,3)), INDEX(Reference_Table!$E$1:$E$3,RANDBETWEEN(1,3))))} -> Nike Running | E5: =RANDBETWEEN(5,100) -> 69 | F5: =IF(C5="Footwear",E5*RANDBETWEEN(50,200), IF(C5="Apparel",E5*RANDBETWEEN(20,100), E5*RANDBETWEEN(20,200))) -> 4761 | G5: =F5*RANDBETWEEN(60,80)/100 -> 3761.19 | H5: =F5-G5 -> 999.81 | I5: =RANDBETWEEN(0,40) -> 8
A6: 45689 | B6: {=INDEX(Reference_Table!$A$1:$A$3,RANDBETWEEN(1,3))} -> Tampa | C6: {=INDEX(Reference_Table!$B$1:$B$3,RANDBETWEEN(1,3))} -> Apparel | D6: {=IF(C6="Footwear",INDEX(Reference_Table!$C$1:$C$3,RANDBETWEEN(1,3)), IF(C6="Apparel",INDEX(Reference_Table!$D$1:$D$3,RANDBETWEEN(1,3)), INDEX(Reference_Table!$E$1:$E$3,RANDBETWEEN(1,3))))} -> Under Armour Hoodie | E6: =RANDBETWEEN(5,100) -> 14 | F6: =IF(C6="Footwear",E6*RANDBETWEEN(50,200), IF(C6="Apparel",E6*RANDBETWEEN(20,100), E6*RANDBETWEEN(20,200))) -> 1358 | G6: =F6*RANDBETWEEN(60,80)/100 -> 828.38 | H6: =F6-G6 -> 529.62 | I6: =RANDBETWEEN(0,40) -> 37
A7: 45689 | B7: {=INDEX(Reference_Table!$A$1:$A$3,RANDBETWEEN(1,3))} -> Clearwater | C7: {=INDEX(Reference_Table!$B$1:$B$3,RANDBETWEEN(1,3))} -> Apparel | D7: {=IF(C7="Footwear",INDEX(Reference_Table!$C$1:$C$3,RANDBETWEEN(1,3)), IF(C7="Apparel",INDEX(Reference_Table!$D$1:$D$3,RANDBETWEEN(1,3)), INDEX(Reference_Table!$E$1:$E$3,RANDBETWEEN(1,3))))} -> Nike Shorts | E7: =RANDBETWEEN(5,100) -> 80 | F7: =IF(C7="Footwear",E7*RANDBETWEEN(50,200), IF(C7="Apparel",E7*RANDBETWEEN(20,100), E7*RANDBETWEEN(20,200))) -> 3840 | G7: =F7*RANDBETWEEN(60,80)/100 -> 2419.2 | H7: =F7-G7 -> 1420.8 | I7: =RANDBETWEEN(0,40) -> 36
A8: 45717 | B8: {=INDEX(Reference_Table!$A$1:$A$3,RANDBETWEEN(1,3))} -> Tampa | C8: {=INDEX(Reference_Table!$B$1:$B$3,RANDBETWEEN(1,3))} -> Footwear | D8: {=IF(C8="Footwear",INDEX(Reference_Table!$C$1:$C$3,RANDBETWEEN(1,3)), IF(C8="Apparel",INDEX(Reference_Table!$D$1:$D$3,RANDBETWEEN(1,3)), INDEX(Reference_Table!$E$1:$E$3,RANDBETWEEN(1,3))))} -> Brooks Running | E8: =RANDBETWEEN(5,100) -> 76 | F8: =IF(C8="Footwear",E8*RANDBETWEEN(50,200), IF(C8="Apparel",E8*RANDBETWEEN(20,100), E8*RANDBETWEEN(20,200))) -> 10032 | G8: =F8*RANDBETWEEN(60,80)/100 -> 6019.2 | H8: =F8-G8 -> 4012.8 | I8: =RANDBETWEEN(0,40) -> 1
A9: 45717 | B9: {=INDEX(Reference_Table!$A$1:$A$3,RANDBETWEEN(1,3))} -> St. Petersburg | C9: {=INDEX(Reference_Table!$B$1:$B$3,RANDBETWEEN(1,3))} -> Equipment | D9: {=IF(C9="Footwear",INDEX(Reference_Table!$C$1:$C$3,RANDBETWEEN(1,3)), IF(C9="Apparel",INDEX(Reference_Table!$D$1:$D$3,RANDBETWEEN(1,3)), INDEX(Reference_Table!$E$1:$E$3,RANDBETWEEN(1,3))))} -> Yoga Mat | E9: =RANDBETWEEN(5,100) -> 99 | F9: =IF(C9="Footwear",E9*RANDBETWEEN(50,200), IF(C9="Apparel",E9*RANDBETWEEN(20,100), E9*RANDBETWEEN(20,200))) -> 15048 | G9: =F9*RANDBETWEEN(60,80)/100 -> 11135.52 | H9: =F9-G9 -> 3912.48 | I9: =RANDBETWEEN(0,40) -> 10
A10: 45717 | B10: {=INDEX(Reference_Table!$A$1:$A$3,RANDBETWEEN(1,3))} -> St. Petersburg | C10: {=INDEX(Reference_Table!$B$1:$B$3,RANDBETWEEN(1,3))} -> Equipment | D10: {=IF(C10="Footwear",INDEX(Reference_Table!$C$1:$C$3,RANDBETWEEN(1,3)), IF(C10="Apparel",INDEX(Reference_Table!$D$1:$D$3,RANDBETWEEN(1,3)), INDEX(Reference_Table!$E$1:$E$3,RANDBETWEEN(1,3))))} -> Yoga Mat | E10: =RANDBETWEEN(5,100) -> 88 | F10: =IF(C10="Footwear",E10*RANDBETWEEN(50,200), IF(C10="Apparel",E10*RANDBETWEEN(20,100), E10*RANDBETWEEN(20,200))) -> 3960 | G10: =F10*RANDBETWEEN(60,80)/100 -> 2851.2 | H10: =F10-G10 -> 1108.8 | I10: =RANDBETWEEN(0,40) -> 3
A11: 45748 | B11: {=INDEX(Reference_Table!$A$1:$A$3,RANDBETWEEN(1,3))} -> Clearwater | C11: {=INDEX(Reference_Table!$B$1:$B$3,RANDBETWEEN(1,3))} -> Equipment | D11: {=IF(C11="Footwear",INDEX(Reference_Table!$C$1:$C$3,RANDBETWEEN(1,3)), IF(C11="Apparel",INDEX(Reference_Table!$D$1:$D$3,RANDBETWEEN(1,3)), INDEX(Reference_Table!$E$1:$E$3,RANDBETWEEN(1,3))))} -> Dumbbell Set | E11: =RANDBETWEEN(5,100) -> 36 | F11: =IF(C11="Footwear",E11*RANDBETWEEN(50,200), IF(C11="Apparel",E11*RANDBETWEEN(20,100), E11*RANDBETWEEN(20,200))) -> 1620 | G11: =F11*RANDBETWEEN(60,80)/100 -> 1020.6 | H11: =F11-G11 -> 599.4 | I11: =RANDBETWEEN(0,40) -> 0
A12: 45748 | B12: {=INDEX(Reference_Table!$A$1:$A$3,RANDBETWEEN(1,3))} -> Clearwater | C12: {=INDEX(Reference_Table!$B$1:$B$3,RANDBETWEEN(1,3))} -> Apparel | D12: {=IF(C12="Footwear",INDEX(Reference_Table!$C$1:$C$3,RANDBETWEEN(1,3)), IF(C12="Apparel",INDEX(Reference_Table!$D$1:$D$3,RANDBETWEEN(1,3)), INDEX(Reference_Table!$E$1:$E$3,RANDBETWEEN(1,3))))} -> Adidas Joggers | E12: =RANDBETWEEN(5,100) -> 43 | F12: =IF(C12="Footwear",E12*RANDBETWEEN(50,200), IF(C12="Apparel",E12*RANDBETWEEN(20,100), E12*RANDBETWEEN(20,200))) -> 4214 | G12: =F12*RANDBETWEEN(60,80)/100 -> 2570.54 | H12: =F12-G12 -> 1643.46 | I12: =RANDBETWEEN(0,40) -> 17
A13: 45748 | B13: {=INDEX(Reference_Table!$A$1:$A$3,RANDBETWEEN(1,3))} -> St. Petersburg | C13: {=INDEX(Reference_Table!$B$1:$B$3,RANDBETWEEN(1,3))} -> Apparel | D13: {=IF(C13="Footwear",INDEX(Reference_Table!$C$1:$C$3,RANDBETWEEN(1,3)), IF(C13="Apparel",INDEX(Reference_Table!$D$1:$D$3,RANDBETWEEN(1,3)), INDEX(Reference_Table!$E$1:$E$3,RANDBETWEEN(1,3))))} -> Nike Shorts | E13: =RANDBETWEEN(5,100) -> 95 | F13: =IF(C13="Footwear",E13*RANDBETWEEN(50,200), IF(C13="Apparel",E13*RANDBETWEEN(20,100), E13*RANDBETWEEN(20,200))) -> 4275 | G13: =F13*RANDBETWEEN(60,80)/100 -> 2992.5 | H13: =F13-G13 -> 1282.5 | I13: =RANDBETWEEN(0,40) -> 38
... A46: 45717 | B46: {=INDEX(Reference_Table!$A$1:$A$3,RANDBETWEEN(1,3))} -> Tampa | C46: {=INDEX(Reference_Table!$B$1:$B$3,RANDBETWEEN(1,3))} -> Apparel | D46: {=IF(C46="Footwear",INDEX(Reference_Table!$C$1:$C$3,RANDBETWEEN(1,3)), IF(C46="Apparel",INDEX(Reference_Table!$D$1:$D$3,RANDBETWEEN(1,3)), INDEX(Reference_Table!$E$1:$E$3,RANDBETWEEN(1,3))))} -> Adidas Joggers | E46: =RANDBETWEEN(5,100) -> 32 | F46: =IF(C46="Footwear",E46*RANDBETWEEN(50,200), IF(C46="Apparel",E46*RANDBETWEEN(20,100), E46*RANDBETWEEN(20,200))) -> 3072 | G46: =F46*RANDBETWEEN(60,80)/100 -> 2365.44 | H46: =F46-G46 -> 706.56 | I46: =RANDBETWEEN(0,40) -> 17

Sheet Reference_Table
A1: Tampa | B1: Footwear | C1: Nike Running | D1: Under Armour Hoodie | E1: Yoga Mat
A2: Clearwater | B2: Apparel | C2: Adidas Sneakers | D2: Nike Shorts | E2: Dumbbell Set
A3: St. Petersburg | B3: Equipment | C3: Brooks Running | D3: Adidas Joggers | E3: Kettlebell

Sheet Analysis
A1: Row Labels | B1: Sum of Revenue | D1: Row Labels | E1: Sum of Revenue | F1: Row Labels | G1: Sum of Revenue | H1: Sum of Cost | I1: Sum of Profit
A2: Jan | B2: 27383 | D2: Adidas Joggers | E2: 19028 | F2: Adidas Joggers | G2: 19028 | H2: 13804.65 | I2: 5223.35
A3: Feb | B3: 40863 | D3: Adidas Sneakers | E3: 34453 | F3: Apparel | G3: 19028 | H3: 13804.65 | I3: 5223.35
A4: Mar | B4: 25613 | D4: Brooks Running | E4: 56027 | F4: Clearwater | G4: 4524 | H4: 2940.6 | I4: 1583.4
A5: Apr | B5: 21430 | D5: Dumbbell Set | E5: 40141 | F5: St. Petersburg | G5: 12595 | H5: 9565.93 | I5: 3029.07
A6: May | B6: 14255 | D6: Kettlebell | E6: 39123 | F6: Tampa | G6: 1909 | H6: 1298.12 | I6: 610.88
A7: Jun | B7: 20001 | D7: Nike Running | E7: 18414 | F7: Adidas Sneakers | G7: 34453 | H7: 23004.95 | I7: 11448.05
A8: Jul | B8: 10038 | D8: Nike Shorts | E8: 9622 | F8: Footwear | G8: 34453 | H8: 23004.95 | I8: 11448.05
A9: Aug | B9: 28083 | D9: Under Armour Hoodie | E9: 7653 | F9: Clearwater | G9: 24722 | H9: 16650.6 | I9: 8071.4
A10: Sep | B10: 26102 | D10: Yoga Mat | E10: 30442 | F10: St. Petersburg | G10: 6811 | H10: 4427.15 | I10: 2383.85
A11: Oct | B11: 9325 | D11: Grand Total | E11: 254903 | F11: Tampa | G11: 2920 | H11: 1927.2 | I11: 992.8
A12: Nov | B12: 17007 | D12: Row Labels | E12: Sum of Inventory | F12: Brooks Running | G12: 56027 | H12: 38868.57 | I12: 17158.43
A13: Dec | B13: 14803 | D13: Adidas Joggers | E13: 125 | F13: Footwear | G13: 56027 | H13: 38868.57 | I13: 17158.43
A14: Grand Total | B14: 254903 | D14: Adidas Sneakers | E14: 92 | F14: Clearwater | G14: 26686 | H14: 17998.52 | I14: 8687.48
A15: Row Labels | B15: Sum of Revenue | D15: Brooks Running | E15: 138 | F15: Tampa | G15: 29341 | H15: 20870.05 | I15: 8470.95
A16: Apparel | B16: 36303 | D16: Dumbbell Set | E16: 118 | F16: Dumbbell Set | G16: 40141 | H16: 30104.47 | I16: 10036.53
A17: Equipment | B17: 109706 | D17: Kettlebell | E17: 69 | F17: Equipment | G17: 40141 | H17: 30104.47 | I17: 10036.53
A18: Footwear | B18: 108894 | D18: Nike Running | E18: 84 | F18: Clearwater | G18: 19921 | H18: 14889.37 | I18: 5031.63
A19: Grand Total | B19: 254903 | D19: Nike Shorts | E19: 85 | F19: St. Petersburg | G19: 13688 | H19: 10250.78 | I19: 3437.22
D20: Under Armour Hoodie | E20: 72 | F20: Tampa | G20: 6532 | H20: 4964.32 | I20: 1567.68
D21: Yoga Mat | E21: 83 | F21: Kettlebell | G21: 39123 | H21: 25755.55 | I21: 13367.45
D22: Grand Total | E22: 866 | F22: Equipment | G22: 39123 | H22: 25755.55 | I22: 13367.45
A23: Row Labels | B23: Sum of Profit | F23: Clearwater | G23: 15252 | H23: 9151.2 | I23: 6100.8
A24: Jan | B24: 7109.47 | F24: St. Petersburg | G24: 10502 | H24: 7561.44 | I24: 2940.56
A25: Feb | B25: 14024.33 | F25: Tampa | G25: 13369 | H25: 9042.91 | I25: 4326.09
A26: Mar | B26: 8178.17 | F26: Nike Running | G26: 18414 | H26: 12760.68 | I26: 5653.32
A27: Apr | B27: 7940.68 | F27: Footwear | G27: 18414 | H27: 12760.68 | I27: 5653.32
A28: May | B28: 3213.37 | F28: Clearwater | G28: 8640 | H28: 5788.8 | I28: 2851.2
A29: Jun | B29: 5414.15 | F29: St. Petersburg | G29: 1632 | H29: 1044.48 | I29: 587.52
A30: Jul | B30: 3315.06 | F30: Tampa | G30: 8142 | H30: 5927.4 | I30: 2214.6
A31: Aug | B31: 9910.35 | F31: Nike Shorts | G31: 9622 | H31: 6581.58 | I31: 3040.42
A32: Sep | B32: 6932.34 | F32: Apparel | G32: 9622 | H32: 6581.58 | I32: 3040.42
A33: Oct | B33: 2797.17 | F33: Clearwater | G33: 3578 | H33: 2347.34 | I33: 1230.66
A34: Nov | B34: 3996 | F34: Tampa | G34: 6044 | H34: 4234.24 | I34: 1809.76
A35: Dec | B35: 4039.02 | F35: Under Armour Hoodie | G35: 7653 | H35: 5012.64 | I35: 2640.36
A36: Grand Total | B36: 76870.11 | F36: Apparel | G36: 7653 | H36: 5012.64 | I36: 2640.36
F37: Clearwater | G37: 2616 | H37: 1839.33 | I37: 776.67
F38: St. Petersburg | G38: 5037 | H38: 3173.31 | I38: 1863.69
F39: Yoga Mat | G39: 30442 | H39: 22139.8 | I39: 8302.2
F40: Equipment | G40: 30442 | H40: 22139.8 | I40: 8302.2
...

Sheet Executive_Dashboard
